Workbook

Sheet Assumptions
B2: Driver Assumptions
B3: Scenario selector drives all operating, capex, debt and DCF inputs. Blue = input.
B5: Fiscal Year | C5: 2023 | D5: 2024 | E5: 2025 | F5: 2026 | G5: 2027 | H5: 2028 | I5: 2029 | J5: 2030
B6: Period type | C6: Actual | D6: Actual | E6: Actual | F6: Estimate | G6: Estimate | H6: Estimate | I6: Estimate | J6: Estimate
B8: SCENARIO SELECTOR (1=Bull 2=Base 3=Bear)
B9: Active scenario → | C9: 2 | D9: =CHOOSE($C$9,"BULL","BASE","BEAR")
B12: OPERATING DRIVERS — scenario inputs
B13: (Bull / Base / Bear stacked; Active = CHOOSE)
B14: Revenue growth %
B15: Bull | C15: - | D15: - | E15: - | F15: 0.14 | G15: 0.13 | H15: 0.12 | I15: 0.1 | J15: 0.09
B16: Base | C16: - | D16: - | E16: - | F16: 0.1 | G16: 0.09 | H16: 0.08 | I16: 0.07 | J16: 0.06
B17: Bear | C17: - | D17: - | E17: - | F17: 0.05 | G17: 0.04 | H17: 0.03 | I17: 0.03 | J17: 0.02
B18: → Active | C18: =IF($C$9=1,C15,IF($C$9=2,C16,C17)) | D18: =IF($C$9=1,D15,IF($C$9=2,D16,D17)) | E18: =IF($C$9=1,E15,IF($C$9=2,E16,E17)) | F18: =IF($C$9=1,F15,IF($C$9=2,F16,F17)) | G18: =IF($C$9=1,G15,IF($C$9=2,G16,G17)) | H18: =IF($C$9=1,H15,IF($C$9=2,H16,H17)) | I18: =IF($C$9=1,I15,IF($C$9=2,I16,I17)) | J18: =IF($C$9=1,J15,IF($C$9=2,J16,J17))
B20: Gross margin %
B21: Bull | C21: 0.42 | D21: 0.43 | E21: 0.44 | F21: 0.46 | G21: 0.47 | H21: 0.48 | I21: 0.48 | J21: 0.49
B22: Base | C22: 0.42 | D22: 0.43 | E22: 0.44 | F22: 0.44 | G22: 0.45 | H22: 0.45 | I22: 0.46 | J22: 0.46
B23: Bear | C23: 0.42 | D23: 0.43 | E23: 0.44 | F23: 0.43 | G23: 0.42 | H23: 0.42 | I23: 0.41 | J23: 0.41
B24: → Active | C24: =IF($C$9=1,C21,IF($C$9=2,C22,C23)) | D24: =IF($C$9=1,D21,IF($C$9=2,D22,D23)) | E24: =IF($C$9=1,E21,IF($C$9=2,E22,E23)) | F24: =IF($C$9=1,F21,IF($C$9=2,F22,F23)) | G24: =IF($C$9=1,G21,IF($C$9=2,G22,G23)) | H24: =IF($C$9=1,H21,IF($C$9=2,H22,H23)) | I24: =IF($C$9=1,I21,IF($C$9=2,I22,I23)) | J24: =IF($C$9=1,J21,IF($C$9=2,J22,J23))
B26: SG&A % of revenue
B27: Bull | C27: 0.18 | D27: 0.18 | E27: 0.17 | F27: 0.16 | G27: 0.15 | H27: 0.15 | I27: 0.14 | J27: 0.14
B28: Base | C28: 0.18 | D28: 0.18 | E28: 0.17 | F28: 0.17 | G28: 0.17 | H28: 0.16 | I28: 0.16 | J28: 0.16
B29: Bear | C29: 0.18 | D29: 0.18 | E29: 0.17 | F29: 0.18 | G29: 0.18 | H29: 0.18 | I29: 0.18 | J29: 0.18
B30: → Active | C30: =IF($C$9=1,C27,IF($C$9=2,C28,C29)) | D30: =IF($C$9=1,D27,IF($C$9=2,D28,D29)) | E30: =IF($C$9=1,E27,IF($C$9=2,E28,E29)) | F30: =IF($C$9=1,F27,IF($C$9=2,F28,F29)) | G30: =IF($C$9=1,G27,IF($C$9=2,G28,G29)) | H30: =IF($C$9=1,H27,IF($C$9=2,H28,H29)) | I30: =IF($C$9=1,I27,IF($C$9=2,I28,I29)) | J30: =IF($C$9=1,J27,IF($C$9=2,J28,J29))
B32: R&D % of revenue
B33: Bull | C33: 0.08 | D33: 0.08 | E33: 0.08 | F33: 0.08 | G33: 0.08 | H33: 0.08 | I33: 0.08 | J33: 0.08
B34: Base | C34: 0.08 | D34: 0.08 | E34: 0.08 | F34: 0.08 | G34: 0.08 | H34: 0.08 | I34: 0.08 | J34: 0.08
B35: Bear | C35: 0.08 | D35: 0.08 | E35: 0.08 | F35: 0.09 | G35: 0.09 | H35: 0.09 | I35: 0.09 | J35: 0.09
B36: → Active | C36: =IF($C$9=1,C33,IF($C$9=2,C34,C35)) | D36: =IF($C$9=1,D33,IF($C$9=2,D34,D35)) | E36: =IF($C$9=1,E33,IF($C$9=2,E34,E35)) | F36: =IF($C$9=1,F33,IF($C$9=2,F34,F35)) | G36: =IF($C$9=1,G33,IF($C$9=2,G34,G35)) | H36: =IF($C$9=1,H33,IF($C$9=2,H34,H35)) | I36: =IF($C$9=1,I33,IF($C$9=2,I34,I35)) | J36: =IF($C$9=1,J33,IF($C$9=2,J34,J35))
B38: Tax rate %
B39: Bull | C39: 0.21 | D39: 0.21 | E39: 0.21 | F39: 0.21 | G39: 0.21 | H39: 0.21 | I39: 0.21 | J39: 0.21
B40: Base | C40: 0.21 | D40: 0.21 | E40: 0.21 | F40: 0.21 | G40: 0.21 | H40: 0.21 | I40: 0.21 | J40: 0.21
B41: Bear | C41: 0.21 | D41: 0.21 | E41: 0.21 | F41: 0.21 | G41: 0.21 | H41: 0.21 | I41: 0.21 | J41: 0.21
B42: → Active | C42: =IF($C$9=1,C39,IF($C$9=2,C40,C41)) | D42: =IF($C$9=1,D39,IF($C$9=2,D40,D41)) | E42: =IF($C$9=1,E39,IF($C$9=2,E40,E41)) | F42: =IF($C$9=1,F39,IF($C$9=2,F40,F41)) | G42: =IF($C$9=1,G39,IF($C$9=2,G40,G41)) | H42: =IF($C$9=1,H39,IF($C$9=2,H40,H41)) | I42: =IF($C$9=1,I39,IF($C$9=2,I40,I41)) | J42: =IF($C$9=1,J39,IF($C$9=2,J40,J41))
B44: Dividend payout %
B45: Bull | C45: 0.15 | D45: 0.15 | E45: 0.15 | F45: 0.15 | G45: 0.15 | H45: 0.15 | I45: 0.15 | J45: 0.15
B46: Base | C46: 0.2 | D46: 0.2 | E46: 0.2 | F46: 0.2 | G46: 0.2 | H46: 0.2 | I46: 0.2 | J46: 0.2
B47: Bear | C47: 0.25 | D47: 0.25 | E47: 0.25 | F47: 0.25 | G47: 0.25 | H47: 0.25 | I47: 0.25 | J47: 0.25
B48: → Active | C48: =IF($C$9=1,C45,IF($C$9=2,C46,C47)) | D48: =IF($C$9=1,D45,IF($C$9=2,D46,D47)) | E48: =IF($C$9=1,E45,IF($C$9=2,E46,E47)) | F48: =IF($C$9=1,F45,IF($C$9=2,F46,F47)) | G48: =IF($C$9=1,G45,IF($C$9=2,G46,G47)) | H48: =IF($C$9=1,H45,IF($C$9=2,H46,H47)) | I48: =IF($C$9=1,I45,IF($C$9=2,I46,I47)) | J48: =IF($C$9=1,J45,IF($C$9=2,J46,J47))
B50: WORKING CAPITAL & CAPEX DRIVERS
B51: Days sales outstanding (DSO) | C51: 45 | D51: 45 | E51: 45 | F51: 45 | G51: 45 | H51: 45 | I51: 45 | J51: 45
...

Sheet Income Statement
B2: Income Statement
B3: Revenue grows via scenario driver. Interest from debt schedule.
B5: ($ in millions) | C5: =Assumptions!C$5 | D5: =Assumptions!D$5 | E5: =Assumptions!E$5 | F5: =Assumptions!F$5 | G5: =Assumptions!G$5 | H5: =Assumptions!H$5 | I5: =Assumptions!I$5 | J5: =Assumptions!J$5
B7: Revenue | C7: =Assumptions!C79 | D7: =Assumptions!D79 | E7: =Assumptions!E79 | F7: =E7*(1+Assumptions!$F$18) | G7: =F7*(1+Assumptions!$G$18) | H7: =G7*(1+Assumptions!$H$18) | I7: =H7*(1+Assumptions!$I$18) | J7: =I7*(1+Assumptions!$J$18)
B8: Cost of goods sold | C8: =Assumptions!C80 | D8: =Assumptions!D80 | E8: =Assumptions!E80 | F8: =F7*(1-Assumptions!$F$24) | G8: =G7*(1-Assumptions!$G$24) | H8: =H7*(1-Assumptions!$H$24) | I8: =I7*(1-Assumptions!$I$24) | J8: =J7*(1-Assumptions!$J$24)
B9: Gross profit | C9: =C7-C8 | D9: =D7-D8 | E9: =E7-E8 | F9: =F7-F8 | G9: =G7-G8 | H9: =H7-H8 | I9: =I7-I8 | J9: =J7-J8
B10: SG&A | C10: =C7*Assumptions!$C$30 | D10: =D7*Assumptions!$D$30 | E10: =E7*Assumptions!$E$30 | F10: =F7*Assumptions!$F$30 | G10: =G7*Assumptions!$G$30 | H10: =H7*Assumptions!$H$30 | I10: =I7*Assumptions!$I$30 | J10: =J7*Assumptions!$J$30
B11: R&D | C11: =C7*Assumptions!$C$36 | D11: =D7*Assumptions!$D$36 | E11: =E7*Assumptions!$E$36 | F11: =F7*Assumptions!$F$36 | G11: =G7*Assumptions!$G$36 | H11: =H7*Assumptions!$H$36 | I11: =I7*Assumptions!$I$36 | J11: =J7*Assumptions!$J$36
B12: EBITDA | C12: =C9-C10-C11 | D12: =D9-D10-D11 | E12: =E9-E10-E11 | F12: =F9-F10-F11 | G12: =G9-G10-G11 | H12: =H9-H10-H11 | I12: =I9-I10-I11 | J12: =J9-J10-J11
B13: Depreciation & amortization | C13: ='PP&E Schedule'!C9 | D13: ='PP&E Schedule'!D9 | E13: ='PP&E Schedule'!E9 | F13: ='PP&E Schedule'!F9 | G13: ='PP&E Schedule'!G9 | H13: ='PP&E Schedule'!H9 | I13: ='PP&E Schedule'!I9 | J13: ='PP&E Schedule'!J9
B14: EBIT (operating income) | C14: =C12-C13 | D14: =D12-D13 | E14: =E12-E13 | F14: =F12-F13 | G14: =G12-G13 | H14: =H12-H13 | I14: =I12-I13 | J14: =J12-J13
B15: Interest expense, net | C15: ='Debt Schedule'!C21 | D15: ='Debt Schedule'!D21 | E15: ='Debt Schedule'!E21 | F15: ='Debt Schedule'!F21 | G15: ='Debt Schedule'!G21 | H15: ='Debt Schedule'!H21 | I15: ='Debt Schedule'!I21 | J15: ='Debt Schedule'!J21
B16: Pre-tax income | C16: =C14-C15 | D16: =D14-D15 | E16: =E14-E15 | F16: =F14-F15 | G16: =G14-G15 | H16: =H14-H15 | I16: =I14-I15 | J16: =J14-J15
B17: Income taxes | C17: =MAX(C16,0)*Assumptions!$C$42 | D17: =MAX(D16,0)*Assumptions!$D$42 | E17: =MAX(E16,0)*Assumptions!$E$42 | F17: =MAX(F16,0)*Assumptions!$F$42 | G17: =MAX(G16,0)*Assumptions!$G$42 | H17: =MAX(H16,0)*Assumptions!$H$42 | I17: =MAX(I16,0)*Assumptions!$I$42 | J17: =MAX(J16,0)*Assumptions!$J$42
B18: Net income | C18: =C16-C17 | D18: =D16-D17 | E18: =E16-E17 | F18: =F16-F17 | G18: =G16-G17 | H18: =H16-H17 | I18: =I16-I17 | J18: =J16-J17
B19: Dividends paid | C19: =C18*Assumptions!$C$48 | D19: =D18*Assumptions!$D$48 | E19: =E18*Assumptions!$E$48 | F19: =F18*Assumptions!$F$48 | G19: =G18*Assumptions!$G$48 | H19: =H18*Assumptions!$H$48 | I19: =I18*Assumptions!$I$48 | J19: =J18*Assumptions!$J$48
B20: Retained earnings addition | C20: =C18-C19 | D20: =D18-D19 | E20: =E18-E19 | F20: =F18-F19 | G20: =G18-G19 | H20: =H18-H19 | I20: =I18-I19 | J20: =J18-J19
B22: EPS (diluted, $) | C22: =C18/C23 | D22: =D18/D23 | E22: =E18/E23 | F22: =F18/F23 | G22: =G18/G23 | H22: =H18/H23 | I22: =I18/I23 | J22: =J18/J23
B23: Diluted shares (mm) | C23: =Assumptions!$C$76 | D23: =Assumptions!$C$76 | E23: =Assumptions!$C$76 | F23: =Assumptions!$C$76 | G23: =Assumptions!$C$76 | H23: =Assumptions!$C$76 | I23: =Assumptions!$C$76 | J23: =Assumptions!$C$76

Sheet Balance Sheet
B2: Balance Sheet
B3: All lines from schedules. Cash from CF. Equity roll-forward. Must balance.
B5: ($ in millions) | C5: =Assumptions!C$5 | D5: =Assumptions!D$5 | E5: =Assumptions!E$5 | F5: =Assumptions!F$5 | G5: =Assumptions!G$5 | H5: =Assumptions!H$5 | I5: =Assumptions!I$5 | J5: =Assumptions!J$5
B7: ASSETS
B8: Cash & equivalents | C8: ='Cash Flow'!C21 | D8: ='Cash Flow'!D21 | E8: ='Cash Flow'!E21 | F8: ='Cash Flow'!F21 | G8: ='Cash Flow'!G21 | H8: ='Cash Flow'!H21 | I8: ='Cash Flow'!I21 | J8: ='Cash Flow'!J21
B9: Accounts receivable | C9: ='WC Schedule'!C7 | D9: ='WC Schedule'!D7 | E9: ='WC Schedule'!E7 | F9: ='WC Schedule'!F7 | G9: ='WC Schedule'!G7 | H9: ='WC Schedule'!H7 | I9: ='WC Schedule'!I7 | J9: ='WC Schedule'!J7
B10: Inventory | C10: ='WC Schedule'!C8 | D10: ='WC Schedule'!D8 | E10: ='WC Schedule'!E8 | F10: ='WC Schedule'!F8 | G10: ='WC Schedule'!G8 | H10: ='WC Schedule'!H8 | I10: ='WC Schedule'!I8 | J10: ='WC Schedule'!J8
B11: Net PP&E | C11: ='PP&E Schedule'!C10 | D11: ='PP&E Schedule'!D10 | E11: ='PP&E Schedule'!E10 | F11: ='PP&E Schedule'!F10 | G11: ='PP&E Schedule'!G10 | H11: ='PP&E Schedule'!H10 | I11: ='PP&E Schedule'!I10 | J11: ='PP&E Schedule'!J10
B12: Total assets | C12: =C8+C9+C10+C11 | D12: =D8+D9+D10+D11 | E12: =E8+E9+E10+E11 | F12: =F8+F9+F10+F11 | G12: =G8+G9+G10+G11 | H12: =H8+H9+H10+H11 | I12: =I8+I9+I10+I11 | J12: =J8+J9+J10+J11
B14: LIABILITIES & EQUITY
B15: Accounts payable | C15: ='WC Schedule'!C9 | D15: ='WC Schedule'!D9 | E15: ='WC Schedule'!E9 | F15: ='WC Schedule'!F9 | G15: ='WC Schedule'!G9 | H15: ='WC Schedule'!H9 | I15: ='WC Schedule'!I9 | J15: ='WC Schedule'!J9
B16: Total debt | C16: ='Debt Schedule'!C19 | D16: ='Debt Schedule'!D19 | E16: ='Debt Schedule'!E19 | F16: ='Debt Schedule'!F19 | G16: ='Debt Schedule'!G19 | H16: ='Debt Schedule'!H19 | I16: ='Debt Schedule'!I19 | J16: ='Debt Schedule'!J19
B17: Common equity | C17: =(C8+C9+C10+C11)-C15-C16 | D17: =C17+'Income Statement'!D20 | E17: =D17+'Income Statement'!E20 | F17: =E17+'Income Statement'!F20 | G17: =F17+'Income Statement'!G20 | H17: =G17+'Income Statement'!H20 | I17: =H17+'Income Statement'!I20 | J17: =I17+'Income Statement'!J20
B18: Total liab. & equity | C18: =C15+C16+C17 | D18: =D15+D16+D17 | E18: =E15+E16+E17 | F18: =F15+F16+F17 | G18: =G15+G16+G17 | H18: =H15+H16+H17 | I18: =I15+I16+I17 | J18: =J15+J16+J17
B20: BALANCE CHECK (=0) | C20: =C12-C18 | D20: =D12-D18 | E20: =E12-E18 | F20: =F12-F18 | G20: =G12-G18 | H20: =H12-H18 | I20: =I12-I18 | J20: =J12-J18

Sheet Cash Flow
B2: Cash Flow Statement
B3: Indirect method. Pre-financing flow feeds revolver logic. Ends → balance sheet cash.
B5: ($ in millions) | C5: =Assumptions!C$5 | D5: =Assumptions!D$5 | E5: =Assumptions!E$5 | F5: =Assumptions!F$5 | G5: =Assumptions!G$5 | H5: =Assumptions!H$5 | I5: =Assumptions!I$5 | J5: =Assumptions!J$5
B7: Net income | C7: ='Income Statement'!C18 | D7: ='Income Statement'!D18 | E7: ='Income Statement'!E18 | F7: ='Income Statement'!F18 | G7: ='Income Statement'!G18 | H7: ='Income Statement'!H18 | I7: ='Income Statement'!I18 | J7: ='Income Statement'!J18
B8: Add: D&A | C8: ='Income Statement'!C13 | D8: ='Income Statement'!D13 | E8: ='Income Statement'!E13 | F8: ='Income Statement'!F13 | G8: ='Income Statement'!G13 | H8: ='Income Statement'!H13 | I8: ='Income Statement'!I13 | J8: ='Income Statement'!J13
B9: Less: change in NWC | C9: ='WC Schedule'!C11 | D9: ='WC Schedule'!D11 | E9: ='WC Schedule'!E11 | F9: ='WC Schedule'!F11 | G9: ='WC Schedule'!G11 | H9: ='WC Schedule'!H11 | I9: ='WC Schedule'!I11 | J9: ='WC Schedule'!J11
B10: Cash flow from operations | C10: =C7+C8-C9 | D10: =D7+D8-D9 | E10: =E7+E8-E9 | F10: =F7+F8-F9 | G10: =G7+G8-G9 | H10: =H7+H8-H9 | I10: =I7+I8-I9 | J10: =J7+J8-J9
B11: Less: capex | C11: ='PP&E Schedule'!C8 | D11: ='PP&E Schedule'!D8 | E11: ='PP&E Schedule'!E8 | F11: ='PP&E Schedule'!F8 | G11: ='PP&E Schedule'!G8 | H11: ='PP&E Schedule'!H8 | I11: ='PP&E Schedule'!I8 | J11: ='PP&E Schedule'!J8
B12: Cash flow from investing | C12: =-C11 | D12: =-D11 | E12: =-E11 | F12: =-F11 | G12: =-G11 | H12: =-H11 | I12: =-I11 | J12: =-J11
B13: Pre-financing cash flow | C13: =C10+C12 | D13: =D10+D12 | E13: =E10+E12 | F13: =F10+F12 | G13: =G10+G12 | H13: =H10+H12 | I13: =I10+I12 | J13: =J10+J12
B14: Beginning cash | C14: =Assumptions!$C$78 | D14: =C21 | E14: =D21 | F14: =E21 | G14: =F21 | H14: =G21 | I14: =H21 | J14: =I21
B15: Cash avail. before revolver | C15: =C14+C13-C16-C17 | D15: =D14+D13-D16-D17 | E15: =E14+E13-E16-E17 | F15: =F14+F13-F16-F17 | G15: =G14+G13-G16-G17 | H15: =H14+H13-H16-H17 | I15: =I14+I13-I16-I17 | J15: =J14+J13-J16-J17
B16: Dividends paid | C16: ='Income Statement'!C19 | D16: ='Income Statement'!D19 | E16: ='Income Statement'!E19 | F16: ='Income Statement'!F19 | G16: ='Income Statement'!G19 | H16: ='Income Statement'!H19 | I16: ='Income Statement'!I19 | J16: ='Income Statement'!J19
B17: Term loan amortization | C17: ='Debt Schedule'!C14 | D17: ='Debt Schedule'!D14 | E17: ='Debt Schedule'!E14 | F17: ='Debt Schedule'!F14 | G17: ='Debt Schedule'!G14 | H17: ='Debt Schedule'!H14 | I17: ='Debt Schedule'!I14 | J17: ='Debt Schedule'!J14
B18: Revolver draw / (repay) | C18: ='Debt Schedule'!C17 | D18: ='Debt Schedule'!D17 | E18: ='Debt Schedule'!E17 | F18: ='Debt Schedule'!F17 | G18: ='Debt Schedule'!G17 | H18: ='Debt Schedule'!H17 | I18: ='Debt Schedule'!I17 | J18: ='Debt Schedule'!J17
B19: Cash flow from financing | C19: =-C16-C17+C18 | D19: =-D16-D17+D18 | E19: =-E16-E17+E18 | F19: =-F16-F17+F18 | G19: =-G16-G17+G18 | H19: =-H16-H17+H18 | I19: =-I16-I17+I18 | J19: =-J16-J17+J18
B20: Net change in cash | C20: =C10+C12+C19 | D20: =D10+D12+D19 | E20: =E10+E12+E19 | F20: =F10+F12+F19 | G20: =G10+G12+G19 | H20: =H10+H12+H19 | I20: =I10+I12+I19 | J20: =J10+J12+J19
B21: Ending cash | C21: =C14+C20 | D21: =D14+D20 | E21: =E14+E20 | F21: =F14+F20 | G21: =G14+G20 | H21: =H14+H20 | I21: =I14+I20 | J21: =J14+J20
B23: CF TIE-OUT vs BS (=0) | C23: =C21-'Balance Sheet'!C8 | D23: =D21-'Balance Sheet'!D8 | E23: =E21-'Balance Sheet'!E8 | F23: =F21-'Balance Sheet'!F8 | G23: =G21-'Balance Sheet'!G8 | H23: =H21-'Balance Sheet'!H8 | I23: =I21-'Balance Sheet'!I8 | J23: =J21-'Balance Sheet'!J8

Sheet PP&E Schedule
B2: PP&E Schedule
B3: Capex roll-forward with straight-line depreciation on opening balance.
B5: ($ in millions) | C5: =Assumptions!C$5 | D5: =Assumptions!D$5 | E5: =Assumptions!E$5 | F5: =Assumptions!F$5 | G5: =Assumptions!G$5 | H5: =Assumptions!H$5 | I5: =Assumptions!I$5 | J5: =Assumptions!J$5
B7: Opening net PP&E | C7: ='Income Statement'!C7*Assumptions!$C$59*6 | D7: =C10 | E7: =D10 | F7: =E10 | G7: =F10 | H7: =G10 | I7: =H10 | J7: =I10
B8: Capex | C8: ='Income Statement'!C7*Assumptions!$C$59 | D8: ='Income Statement'!D7*Assumptions!$D$59 | E8: ='Income Statement'!E7*Assumptions!$E$59 | F8: ='Income Statement'!F7*Assumptions!$F$59 | G8: ='Income Statement'!G7*Assumptions!$G$59 | H8: ='Income Statement'!H7*Assumptions!$H$59 | I8: ='Income Statement'!I7*Assumptions!$I$59 | J8: ='Income Statement'!J7*Assumptions!$J$59
B9: Depreciation | C9: =C7/$C$11 | D9: =D7/$C$11 | E9: =E7/$C$11 | F9: =F7/$C$11 | G9: =G7/$C$11 | H9: =H7/$C$11 | I9: =I7/$C$11 | J9: =J7/$C$11
B10: Closing net PP&E | C10: =C7+C8-C9 | D10: =D7+D8-D9 | E10: =E7+E8-E9 | F10: =F7+F8-F9 | G10: =G7+G8-G9 | H10: =H7+H8-H9 | I10: =I7+I8-I9 | J10: =J7+J8-J9
B11: Useful life (years, input) | C11: 10

Sheet Debt Schedule
B2: Debt Schedule
B3: Term loan with scheduled amort + revolver. Interest on avg balance. Circular toggle on Assumptions.
B5: DEBT INPUTS (blue)
B6: Term loan opening balance | C6: 5000
B7: Mandatory amortization / yr | C7: 250
B8: Term loan interest rate | C8: 0.055
B9: Revolver interest rate | C9: 0.065
B10: Minimum cash balance | C10: 1000
C12: =Assumptions!C$5 | D12: =Assumptions!D$5 | E12: =Assumptions!E$5 | F12: =Assumptions!F$5 | G12: =Assumptions!G$5 | H12: =Assumptions!H$5 | I12: =Assumptions!I$5 | J12: =Assumptions!J$5
B13: Term loan — opening | C13: =$C$6 | D13: =C15 | E13: =D15 | F13: =E15 | G13: =F15 | H13: =G15 | I13: =H15 | J13: =I15
B14: Term loan — amortization | C14: =MIN($C$7,C13) | D14: =MIN($C$7,D13) | E14: =MIN($C$7,E13) | F14: =MIN($C$7,F13) | G14: =MIN($C$7,G13) | H14: =MIN($C$7,H13) | I14: =MIN($C$7,I13) | J14: =MIN($C$7,J13)
B15: Term loan — closing | C15: =C13-C14 | D15: =D13-D14 | E15: =E13-E14 | F15: =F13-F14 | G15: =G13-G14 | H15: =H13-H14 | I15: =I13-I14 | J15: =J13-J14
B16: Revolver — opening | C16: 0 | D16: =C18 | E16: =D18 | F16: =E18 | G16: =F18 | H16: =G18 | I16: =H18 | J16: =I18
B17: Revolver — draw / (repay) | C17: =MAX(0,$C$10-C22)-MIN(C16,MAX(0,C22-$C$10)) | D17: =MAX(0,$C$10-D22)-MIN(D16,MAX(0,D22-$C$10)) | E17: =MAX(0,$C$10-E22)-MIN(E16,MAX(0,E22-$C$10)) | F17: =MAX(0,$C$10-F22)-MIN(F16,MAX(0,F22-$C$10)) | G17: =MAX(0,$C$10-G22)-MIN(G16,MAX(0,G22-$C$10)) | H17: =MAX(0,$C$10-H22)-MIN(H16,MAX(0,H22-$C$10)) | I17: =MAX(0,$C$10-I22)-MIN(I16,MAX(0,I22-$C$10)) | J17: =MAX(0,$C$10-J22)-MIN(J16,MAX(0,J22-$C$10))
B18: Revolver — closing | C18: =C16+C17 | D18: =D16+D17 | E18: =E16+E17 | F18: =F16+F17 | G18: =G16+G17 | H18: =H16+H17 | I18: =I16+I17 | J18: =J16+J17
B19: Total debt (closing) | C19: =C15+C18 | D19: =D15+D18 | E19: =E15+E18 | F19: =F15+F18 | G19: =G15+G18 | H19: =H15+H18 | I19: =I15+I18 | J19: =J15+J18
B20: Average total debt | C20: =IF(Assumptions!$C$73=1,(C13+C15)/2+(C16+C18)/2,C13+C16) | D20: =IF(Assumptions!$C$73=1,(D13+D15)/2+(D16+D18)/2,D13+D16) | E20: =IF(Assumptions!$C$73=1,(E13+E15)/2+(E16+E18)/2,E13+E16) | F20: =IF(Assumptions!$C$73=1,(F13+F15)/2+(F16+F18)/2,F13+F16) | G20: =IF(Assumptions!$C$73=1,(G13+G15)/2+(G16+G18)/2,G13+G16) | H20: =IF(Assumptions!$C$73=1,(H13+H15)/2+(H16+H18)/2,H13+H16) | I20: =IF(Assumptions!$C$73=1,(I13+I15)/2+(I16+I18)/2,I13+I16) | J20: =IF(Assumptions!$C$73=1,(J13+J15)/2+(J16+J18)/2,J13+J16)
B21: Interest expense | C21: =IF(Assumptions!$C$73=1,$C$8*(C13+C15)/2+$C$9*(C16+C18)/2,$C$8*C13+$C$9*C16) | D21: =IF(Assumptions!$C$73=1,$C$8*(D13+D15)/2+$C$9*(D16+D18)/2,$C$8*D13+$C$9*D16) | E21: =IF(Assumptions!$C$73=1,$C$8*(E13+E15)/2+$C$9*(E16+E18)/2,$C$8*E13+$C$9*E16) | F21: =IF(Assumptions!$C$73=1,$C$8*(F13+F15)/2+$C$9*(F16+F18)/2,$C$8*F13+$C$9*F16) | G21: =IF(Assumptions!$C$73=1,$C$8*(G13+G15)/2+$C$9*(G16+G18)/2,$C$8*G13+$C$9*G16) | H21: =IF(Assumptions!$C$73=1,$C$8*(H13+H15)/2+$C$9*(H16+H18)/2,$C$8*H13+$C$9*H16) | I21: =IF(Assumptions!$C$73=1,$C$8*(I13+I15)/2+$C$9*(I16+I18)/2,$C$8*I13+$C$9*I16) | J21: =IF(Assumptions!$C$73=1,$C$8*(J13+J15)/2+$C$9*(J16+J18)/2,$C$8*J13+$C$9*J16)
B22: Cash avail. for debt service (pre-revolver) | C22: ='Cash Flow'!C15 | D22: ='Cash Flow'!D15 | E22: ='Cash Flow'!E15 | F22: ='Cash Flow'!F15 | G22: ='Cash Flow'!G15 | H22: ='Cash Flow'!H15 | I22: ='Cash Flow'!I15 | J22: ='Cash Flow'!J15
B24: CREDIT METRICS
B25: Net debt / EBITDA | C25: =(C19-'Cash Flow'!C21)/'Income Statement'!C12 | D25: =(D19-'Cash Flow'!D21)/'Income Statement'!D12 | E25: =(E19-'Cash Flow'!E21)/'Income Statement'!E12 | F25: =(F19-'Cash Flow'!F21)/'Income Statement'!F12 | G25: =(G19-'Cash Flow'!G21)/'Income Statement'!G12 | H25: =(H19-'Cash Flow'!H21)/'Income Statement'!H12 | I25: =(I19-'Cash Flow'!I21)/'Income Statement'!I12 | J25: =(J19-'Cash Flow'!J21)/'Income Statement'!J12
B26: EBIT interest coverage | C26: ='Income Statement'!C14/C21 | D26: ='Income Statement'!D14/D21 | E26: ='Income Statement'!E14/E21 | F26: ='Income Statement'!F14/F21 | G26: ='Income Statement'!G14/G21 | H26: ='Income Statement'!H14/H21 | I26: ='Income Statement'!I14/I21 | J26: ='Income Statement'!J14/J21
B27: Debt service coverage (EBITDA/(int+amort)) | C27: ='Income Statement'!C12/(C21+C14) | D27: ='Income Statement'!D12/(D21+D14) | E27: ='Income Statement'!E12/(E21+E14) | F27: ='Income Statement'!F12/(F21+F14) | G27: ='Income Statement'!G12/(G21+G14) | H27: ='Income Statement'!H12/(H21+H14) | I27: ='Income Statement'!I12/(I21+I14) | J27: ='Income Statement'!J12/(J21+J14)

Sheet WC Schedule
B2: Working Capital Schedule
B3: AR/Inv/AP from days metrics → net working capital feeds balance sheet.
B5: ($ in millions) | C5: =Assumptions!C$5 | D5: =Assumptions!D$5 | E5: =Assumptions!E$5 | F5: =Assumptions!F$5 | G5: =Assumptions!G$5 | H5: =Assumptions!H$5 | I5: =Assumptions!I$5 | J5: =Assumptions!J$5
B7: Accounts receivable (DSO) | C7: =Assumptions!$C$51/365*'Income Statement'!C7 | D7: =Assumptions!$D$51/365*'Income Statement'!D7 | E7: =Assumptions!$E$51/365*'Income Statement'!E7 | F7: =Assumptions!$F$51/365*'Income Statement'!F7 | G7: =Assumptions!$G$51/365*'Income Statement'!G7 | H7: =Assumptions!$H$51/365*'Income Statement'!H7 | I7: =Assumptions!$I$51/365*'Income Statement'!I7 | J7: =Assumptions!$J$51/365*'Income Statement'!J7
B8: Inventory (DIO) | C8: =Assumptions!$C$52/365*'Income Statement'!C8 | D8: =Assumptions!$D$52/365*'Income Statement'!D8 | E8: =Assumptions!$E$52/365*'Income Statement'!E8 | F8: =Assumptions!$F$52/365*'Income Statement'!F8 | G8: =Assumptions!$G$52/365*'Income Statement'!G8 | H8: =Assumptions!$H$52/365*'Income Statement'!H8 | I8: =Assumptions!$I$52/365*'Income Statement'!I8 | J8: =Assumptions!$J$52/365*'Income Statement'!J8
B9: Accounts payable (DPO) | C9: =Assumptions!$C$53/365*'Income Statement'!C8 | D9: =Assumptions!$D$53/365*'Income Statement'!D8 | E9: =Assumptions!$E$53/365*'Income Statement'!E8 | F9: =Assumptions!$F$53/365*'Income Statement'!F8 | G9: =Assumptions!$G$53/365*'Income Statement'!G8 | H9: =Assumptions!$H$53/365*'Income Statement'!H8 | I9: =Assumptions!$I$53/365*'Income Statement'!I8 | J9: =Assumptions!$J$53/365*'Income Statement'!J8
B10: Net working capital | C10: =C7+C8-C9 | D10: =D7+D8-D9 | E10: =E7+E8-E9 | F10: =F7+F8-F9 | G10: =G7+G8-G9 | H10: =H7+H8-H9 | I10: =I7+I8-I9 | J10: =J7+J8-J9
B11: Change in NWC (use of cash) | C11: 0 | D11: =D10-C10 | E11: =E10-D10 | F11: =F10-E10 | G11: =G10-F10 | H11: =H10-G10 | I11: =I10-H10 | J11: =J10-I10

Sheet DCF
B2: DCF Valuation — FCFF
B3: Scenario-aware WACC, beta, g, exit multiple. TV = avg(Gordon, exit).
B5: WACC (active scenario)
B6: Cost of equity (CAPM) | C6: =Assumptions!$C$69+Assumptions!$F$65*Assumptions!$F$64
B7: After-tax cost of debt | C7: =Assumptions!$C$70*(1-Assumptions!$F$42)
B8: Equity weight | C8: =1-C9
B9: Debt weight | C9: =Assumptions!$C$71
B10: WACC | C10: =(1-Assumptions!$C$71)*(Assumptions!$C$69+Assumptions!$F$65*Assumptions!$F$64)+Assumptions!$C$71*(Assumptions!$C$70*(1-Assumptions!$F$42))
B12: UNLEVERED FREE CASH FLOW (forecast years)
B13: Year | C13: =Assumptions!F5 | D13: =Assumptions!G5 | E13: =Assumptions!H5 | F13: =Assumptions!I5 | G13: =Assumptions!J5
B14: EBIT | C14: ='Income Statement'!F14 | D14: ='Income Statement'!G14 | E14: ='Income Statement'!H14 | F14: ='Income Statement'!I14 | G14: ='Income Statement'!J14
B15: Taxes on EBIT | C15: =C14*Assumptions!$F$42 | D15: =D14*Assumptions!$G$42 | E15: =E14*Assumptions!$H$42 | F15: =F14*Assumptions!$I$42 | G15: =G14*Assumptions!$J$42
B16: NOPAT | C16: =C14-C15 | D16: =D14-D15 | E16: =E14-E15 | F16: =F14-F15 | G16: =G14-G15
B17: Add: D&A | C17: ='Income Statement'!F13 | D17: ='Income Statement'!G13 | E17: ='Income Statement'!H13 | F17: ='Income Statement'!I13 | G17: ='Income Statement'!J13
B18: Less: capex | C18: ='PP&E Schedule'!F8 | D18: ='PP&E Schedule'!G8 | E18: ='PP&E Schedule'!H8 | F18: ='PP&E Schedule'!I8 | G18: ='PP&E Schedule'!J8
B19: Less: ΔNWC | C19: ='WC Schedule'!F11 | D19: ='WC Schedule'!G11 | E19: ='WC Schedule'!H11 | F19: ='WC Schedule'!I11 | G19: ='WC Schedule'!J11
B20: Unlevered FCFF | C20: =C16+C17-C18-C19 | D20: =D16+D17-D18-D19 | E20: =E16+E17-E18-E19 | F20: =F16+F17-F18-F19 | G20: =G16+G17-G18-G19
B21: Discount period | C21: =1-Assumptions!$C$72*0.5 | D21: =2-Assumptions!$C$72*0.5 | E21: =3-Assumptions!$C$72*0.5 | F21: =4-Assumptions!$C$72*0.5 | G21: =5-Assumptions!$C$72*0.5
B22: Discount factor | C22: =1/(1+DCF!$C$10)^C21 | D22: =1/(1+DCF!$C$10)^D21 | E22: =1/(1+DCF!$C$10)^E21 | F22: =1/(1+DCF!$C$10)^F21 | G22: =1/(1+DCF!$C$10)^G21
B23: PV of FCFF | C23: =C20*C22 | D23: =D20*D22 | E23: =E20*E22 | F23: =F20*F22 | G23: =G20*G22
B25: ENTERPRISE → EQUITY VALUE
B26: Sum PV explicit FCFF | C26: =SUM(C23:G23)
B27: Terminal value (Gordon) | C27: =G20*(1+Assumptions!$F$63)/(DCF!$C$10-Assumptions!$F$63)
B28: Terminal value (exit mult) | C28: ='Income Statement'!J12*Assumptions!$F$66
B29: Terminal value (used = avg) | C29: =AVERAGE(C27,C28)
B30: PV of terminal value | C30: =C29/(1+DCF!$C$10)^G21
B31: Enterprise value | C31: =C26+C30
B32: Less: net debt (latest) | C32: =-('Debt Schedule'!C19-Assumptions!$C$78)
B33: Equity value | C33: =C31+C32
B34: Shares outstanding (mm) | C34: =Assumptions!$C$76
B35: Implied value per share | C35: =C33/C34
B36: Current price | C36: =Assumptions!$C$77
B37: Upside / (downside) | C37: =C35/C36-1
B38: TV as % of EV (flag >80%) | C38: =C30/C31

Sheet Comps
B2: Trading Comparables
B3: Peer multiples → implied value triangulation. Blue = input peer data.
B6: Peer / Metric | C6: EV/Sales | D6: EV/EBITDA | E6: P/E | F6: P/FCF
B7: Peer A | C7: 3 | D7: 12 | E7: 18 | F7: 20
B8: Peer B | C8: 3 | D8: 12 | E8: 18 | F8: 20
B9: Peer C | C9: 3 | D9: 12 | E9: 18 | F9: 20
B10: Peer D | C10: 3 | D10: 12 | E10: 18 | F10: 20
B11: Median | C11: =MEDIAN(C7:C10) | D11: =MEDIAN(D7:D10) | E11: =MEDIAN(E7:E10) | F11: =MEDIAN(F7:F10)
B13: IMPLIED EQUITY VALUE PER SHARE
B14: From EV/Sales | E14: =(C11*'Income Statement'!F7-('Debt Schedule'!C19-Assumptions!$C$78))/Assumptions!$C$76
B15: From EV/EBITDA | E15: =(D11*'Income Statement'!F12-('Debt Schedule'!C19-Assumptions!$C$78))/Assumptions!$C$76
B16: From P/E | E16: =E11*'Income Statement'!F18/Assumptions!$C$76
B17: Average implied value/share | E17: =AVERAGE(E14:E16)

Sheet Scenario & Sensitivity
B2: Scenario & Sensitivity
B3: Switch scenario on Assumptions!C9 to compare. Sensitivity grid = WACC × g.
B6: VALUE PER SHARE — WACC × terminal growth
B8: WACC \ g | C8: =Assumptions!$F$63+-0.01 | D8: =Assumptions!$F$63+-0.005 | E8: =Assumptions!$F$63+0 | F8: =Assumptions!$F$63+0.005 | G8: =Assumptions!$F$63+0.01
B9: =DCF!$C$10+-0.01 | C9: =(DCF!$C$26+(DCF!$G$20*(1+C$8)/($B9-C$8))/(1+$B9)^DCF!$G$21+DCF!$C$32)/DCF!$C$34 | D9: =(DCF!$C$26+(DCF!$G$20*(1+D$8)/($B9-D$8))/(1+$B9)^DCF!$G$21+DCF!$C$32)/DCF!$C$34 | E9: =(DCF!$C$26+(DCF!$G$20*(1+E$8)/($B9-E$8))/(1+$B9)^DCF!$G$21+DCF!$C$32)/DCF!$C$34 | F9: =(DCF!$C$26+(DCF!$G$20*(1+F$8)/($B9-F$8))/(1+$B9)^DCF!$G$21+DCF!$C$32)/DCF!$C$34 | G9: =(DCF!$C$26+(DCF!$G$20*(1+G$8)/($B9-G$8))/(1+$B9)^DCF!$G$21+DCF!$C$32)/DCF!$C$34
B10: =DCF!$C$10+-0.005 | C10: =(DCF!$C$26+(DCF!$G$20*(1+C$8)/($B10-C$8))/(1+$B10)^DCF!$G$21+DCF!$C$32)/DCF!$C$34 | D10: =(DCF!$C$26+(DCF!$G$20*(1+D$8)/($B10-D$8))/(1+$B10)^DCF!$G$21+DCF!$C$32)/DCF!$C$34 | E10: =(DCF!$C$26+(DCF!$G$20*(1+E$8)/($B10-E$8))/(1+$B10)^DCF!$G$21+DCF!$C$32)/DCF!$C$34 | F10: =(DCF!$C$26+(DCF!$G$20*(1+F$8)/($B10-F$8))/(1+$B10)^DCF!$G$21+DCF!$C$32)/DCF!$C$34 | G10: =(DCF!$C$26+(DCF!$G$20*(1+G$8)/($B10-G$8))/(1+$B10)^DCF!$G$21+DCF!$C$32)/DCF!$C$34
B11: =DCF!$C$10+0 | C11: =(DCF!$C$26+(DCF!$G$20*(1+C$8)/($B11-C$8))/(1+$B11)^DCF!$G$21+DCF!$C$32)/DCF!$C$34 | D11: =(DCF!$C$26+(DCF!$G$20*(1+D$8)/($B11-D$8))/(1+$B11)^DCF!$G$21+DCF!$C$32)/DCF!$C$34 | E11: =(DCF!$C$26+(DCF!$G$20*(1+E$8)/($B11-E$8))/(1+$B11)^DCF!$G$21+DCF!$C$32)/DCF!$C$34 | F11: =(DCF!$C$26+(DCF!$G$20*(1+F$8)/($B11-F$8))/(1+$B11)^DCF!$G$21+DCF!$C$32)/DCF!$C$34 | G11: =(DCF!$C$26+(DCF!$G$20*(1+G$8)/($B11-G$8))/(1+$B11)^DCF!$G$21+DCF!$C$32)/DCF!$C$34
B12: =DCF!$C$10+0.005 | C12: =(DCF!$C$26+(DCF!$G$20*(1+C$8)/($B12-C$8))/(1+$B12)^DCF!$G$21+DCF!$C$32)/DCF!$C$34 | D12: =(DCF!$C$26+(DCF!$G$20*(1+D$8)/($B12-D$8))/(1+$B12)^DCF!$G$21+DCF!$C$32)/DCF!$C$34 | E12: =(DCF!$C$26+(DCF!$G$20*(1+E$8)/($B12-E$8))/(1+$B12)^DCF!$G$21+DCF!$C$32)/DCF!$C$34 | F12: =(DCF!$C$26+(DCF!$G$20*(1+F$8)/($B12-F$8))/(1+$B12)^DCF!$G$21+DCF!$C$32)/DCF!$C$34 | G12: =(DCF!$C$26+(DCF!$G$20*(1+G$8)/($B12-G$8))/(1+$B12)^DCF!$G$21+DCF!$C$32)/DCF!$C$34
B13: =DCF!$C$10+0.01 | C13: =(DCF!$C$26+(DCF!$G$20*(1+C$8)/($B13-C$8))/(1+$B13)^DCF!$G$21+DCF!$C$32)/DCF!$C$34 | D13: =(DCF!$C$26+(DCF!$G$20*(1+D$8)/($B13-D$8))/(1+$B13)^DCF!$G$21+DCF!$C$32)/DCF!$C$34 | E13: =(DCF!$C$26+(DCF!$G$20*(1+E$8)/($B13-E$8))/(1+$B13)^DCF!$G$21+DCF!$C$32)/DCF!$C$34 | F13: =(DCF!$C$26+(DCF!$G$20*(1+F$8)/($B13-F$8))/(1+$B13)^DCF!$G$21+DCF!$C$32)/DCF!$C$34 | G13: =(DCF!$C$26+(DCF!$G$20*(1+G$8)/($B13-G$8))/(1+$B13)^DCF!$G$21+DCF!$C$32)/DCF!$C$34

Sheet Checks
B2: Integrity Checks
B3: All must read OK / 0. Agent refuses delivery otherwise.
B5: Check | C5: Result
B6: Balance sheet balances (max abs) | C6: =SUMPRODUCT(MAX(ABS('Balance Sheet'!C20:J20)))
B7: Cash flow ties to BS (max abs) | C7: =SUMPRODUCT(MAX(ABS('Cash Flow'!C23:J23)))
B8: WACC > terminal growth | C8: =IF(DCF!$C$10>Assumptions!$F$63,"OK","FAIL")
B9: Terminal value < 80% of EV | C9: =IF(DCF!C38<0.8,"OK","REVIEW")
B10: Min interest coverage > 2.0x | C10: =IF(MIN('Debt Schedule'!C26:J26)>2,"OK","REVIEW")
B11: Revolver non-negative all years | C11: =IF(MIN('Debt Schedule'!C18:J18)>=0,"OK","FAIL")
B12: Scenario selector valid (1-3) | C12: =IF(AND(Assumptions!$C$9>=1,Assumptions!$C$9<=3),"OK","FAIL")
